Workbook

Sheet Formulas DG
A4: =COUNTA(AC4:XFD4)-1 -> 0 | AC4: VARIABLES
A5: DATOS GENERALES | AC5: Categ_01
AC6: Categ_02
AC7: Categ_03
AC8: Categ_04
AC9: Categ_05
AC10: Categ_06
AC11: Categ_07
AC12: Categ_08
AC13: Categ_09
AC14: Categ_10
AC15: Categ_11
AC16: Categ_12
AC17: Categ_13
... AC20: Categ_16
A21: GENERAL DATA | AC21: Categ_17
AC22: Categ_18
AC23: Categ_19
AC24: Categ_20
AC25: SubCat_01
AC26: SubCat_02
AC27: SubCat_03
AC28: SubCat_04
AC29: SubCat_05
AC30: SubCat_06
AC31: SubCat_07
AC32: SubCat_08
AC33: SubCat_09
... AC36: SubCat_12
A37: V - 8.3
AC38: FORMULARIO
AC39: Tit. Categoria
AC40: Desc. Categoría
AC41: Tit. Subcategoría
AC42: Desc. Subcategoría
AC43: Retroalim. General
AC44: Retroalim. R Correcta
AC45: Retroalim. R Parc Correcta
AC46: Retroalim. R Incorrecta
AC47: Prefijo Preguntas
...

Sheet Formulas OM
AD1: =IFERROR(HLOOKUP(AD4,$AB$4:AC4,1,0),"OK") -> OK
AD2: =COUNTA(AD5:AD36) -> 1
AD3: =COUNTA(AD39:AD79) -> 14
A4: =COUNTA(AC4:XFD4)-1 -> 1 | AC4: VARIABLES | AD4: NUM ROMANOS
A5: OPCION MULTIPLE | AC5: DATO_01 | AD5: =ALEATORIO.ENTRE(1;100)
AC6: DATO_02
AC7: DATO_03
AC8: DATO_04
AC9: DATO_05
AC10: DATO_06
AC11: DATO_07
AC12: DATO_08
AC13: DATO_09
AC14: DATO_10
AC15: DATO_11
AC16: DATO_12
AC17: DATO_13
... AC20: DATO_16
A21: MULTIPLE CHOICE | AC21: DATO_17
AC22: DATO_18
AC23: DATO_19
AC24: DATO_20
AC25: DATO_21
AC26: DATO_22
AC27: DATO_23
AC28: DATO_24
AC29: DATO_25
AC30: DATO_26
AC31: DATO_27
AC32: DATO_28
AC33: DATO_29
... AC36: DATO_32
A37: ='Formulas DG'!A37 -> V - 8.3
AC38: FORMULARIO
AC39: DESCRIPCION | AD39: Numeros Romanos
AC40: ENUNCIADO | AD40: ="El Numero Romano de "&Dato_01&" es:"
AC41: RESPUESTA 1 | AD41: =NUMERO.ROMANO(Dato_01)
AC42: RESPUESTA 2 | AD42: =NUMERO.ROMANO(Dato_01+ALEATORIO.ENTRE(1;3)*10)
AC43: RESPUESTA 3 | AD43: =NUMERO.ROMANO(Dato_01+ALEATORIO.ENTRE(4;5))
AC44: RESPUESTA 4 | AD44: =NUMERO.ROMANO(Dato_01+ALEATORIO.ENTRE(6;8)*10)
...

Sheet Formulas O2
AD1: OK
AD2: 1
AD3: 12
A4: =COUNTA(AC4:XFD4)-1 -> 1 | AC4: VARIABLES | AD4: NUM ROMANOS (OM Varias Respuestas)
A5: OPCION MULTIPLE + | AC5: DATO_01 | AD5: =ALEATORIO.ENTRE(10;100)
AC6: DATO_02
AC7: DATO_03
AC8: DATO_04
AC9: DATO_05
AC10: DATO_06
AC11: DATO_07
AC12: DATO_08
AC13: DATO_09
AC14: DATO_10
AC15: DATO_11
AC16: DATO_12
AC17: DATO_13
... AC20: DATO_16
A21: MULTIPLE CHOICE + | AC21: DATO_17
AC22: DATO_18
AC23: DATO_19
AC24: DATO_20
AC25: DATO_21
AC26: DATO_22
AC27: DATO_23
AC28: DATO_24
AC29: DATO_25
AC30: DATO_26
AC31: DATO_27
AC32: DATO_28
AC33: DATO_29
... AC36: DATO_32
A37: ='Formulas OM'!A37 -> V - 8.3
AC38: FORMULARIO
AC39: DESCRIPCION | AD39: Numeros Romanos
AC40: ENUNCIADO | AD40: ="Indica los Números Romanos mayores que "&Dato_01&"."
AC41: RESPUESTA 1 | AD41: =NUMERO.ROMANO(Dato_01+ALEATORIO.ENTRE(1;5))
AC42: RESPUESTA 2 | AD42: =NUMERO.ROMANO(Dato_01+ALEATORIO.ENTRE(6;15))
AC43: RESPUESTA 3 | AD43: =NUMERO.ROMANO(Dato_01-ALEATORIO.ENTRE(1;5))
AC44: RESPUESTA 4 | AD44: =NUMERO.ROMANO(MAX(Dato_01-ALEATORIO.ENTRE(6;10);1))
...

Sheet Formulas VF
AD1: OK
AD2: 7
AD3: 5
A4: =COUNTA(AC4:XFD4)-1 -> 1 | AC4: VARIABLES | AD4: NUM ROMANOS (V/F)
A5: VERDADERO / FALSO | AC5: DATO_01 | AD5: =ALEATORIO.ENTRE(1;100)
AC6: DATO_02 | AD6: =NUMERO.ROMANO(Dato_01)
AC7: DATO_03 | AD7: =NUMERO.ROMANO(Dato_01+ALEATORIO.ENTRE(1;10))
AC8: DATO_04 | AD8: =ALEATORIO.ENTRE(2;3)
AC9: DATO_05
AC10: DATO_06
AC11: DATO_07
AC12: DATO_08
AC13: DATO_09
AC14: DATO_10
AC15: DATO_11
AC16: DATO_12
AC17: DATO_13
AC18: DATO_14
AC19: DATO_15
AC20: DATO_16
A21: TRUE / FALSE | AC21: DATO_17
AC22: DATO_18 | AD22: TRUE
AC23: DATO_19 | AD23: FALSE
AC24: DATO_20 | AD24: =SI(Dato_04=2;Dato_18;Dato_19)
AC25: DATO_21
AC26: DATO_22
AC27: DATO_23
AC28: DATO_24
AC29: DATO_25
AC30: DATO_26
AC31: DATO_27
AC32: DATO_28
AC33: DATO_29
AC34: DATO_30
AC35: DATO_31
AC36: DATO_32
A37: ='Formulas OM'!A37 -> V - 8.3
AC38: FORMULARIO
AC39: DESCRIPCION | AD39: Numeros Romanos
AC40: ENUNCIADO | AD40: ="El Número Romano de "&Dato_01&" es: "&INDIRECTO("Dato_0"&Dato_04)
...

Sheet Formulas EM
AD1: OK
AD2: 0
AD3: 26
A4: =COUNTA(AC4:XFD4)-1 -> 1 | AC4: VARIABLES | AD4: NUM ROMANOS (Emparejar)
A5: EMPAREJAR | AC5: DATO_01
AC6: DATO_02
AC7: DATO_03
AC8: DATO_04
AC9: DATO_05
AC10: DATO_06
AC11: DATO_07
AC12: DATO_08
AC13: DATO_09
AC14: DATO_10
AC15: DATO_11
AC16: DATO_12
AC17: DATO_13
... AC20: DATO_16
A21: MATCHING | AC21: DATO_17
AC22: DATO_18
AC23: DATO_19
AC24: DATO_20
AC25: DATO_21
AC26: DATO_22
AC27: DATO_23
AC28: DATO_24
AC29: DATO_25
AC30: DATO_26
AC31: DATO_27
AC32: DATO_28
AC33: DATO_29
... AC36: DATO_32
A37: ='Formulas OM'!A37 -> V - 8.3
AC38: FORMULARIO
AC39: DESCRIPCION | AD39: Numeros Romanos
AC40: ENUNCIADO | AD40: Empareja:
AC41: P_01_1 | AD41: =ALEATORIO.ENTRE(1;10)
AC42: P_01_2 | AD42: =NUMERO.ROMANO(P_01_1)
AC43: P_02_1 | AD43: =ALEATORIO.ENTRE(11;20)
AC44: P_02_2 | AD44: =NUMERO.ROMANO(P_02_1)
...

Sheet Formulas RC
AD1: =IFERROR(HLOOKUP(AD4,$AB$4:AC4,1,0),"OK") -> OK
AD2: =COUNTA(AD5:AD36) -> 1
AD3: =COUNTA(AD39:AD79) -> 9
A4: =COUNTA(AC4:XFD4)-1 -> 1 | AC4: VARIABLES | AD4: NUM ROMANO (Mayusc y Minus)
A5: RESPUESTA CORTA | AC5: DATO_01 | AD5: =ALEATORIO.ENTRE(5;100)
AC6: DATO_02
AC7: DATO_03
AC8: DATO_04
AC9: DATO_05
AC10: DATO_06
AC11: DATO_07
AC12: DATO_08
AC13: DATO_09
AC14: DATO_10
AC15: DATO_11
AC16: DATO_12
AC17: DATO_13
... AC20: DATO_16
A21: SHORT ANSWER | AC21: DATO_17
AC22: DATO_18
AC23: DATO_19
AC24: DATO_20
AC25: DATO_21
AC26: DATO_22
AC27: DATO_23
AC28: DATO_24
AC29: DATO_25
AC30: DATO_26
AC31: DATO_27
AC32: DATO_28
AC33: DATO_29
... AC36: DATO_32
A37: ='Formulas OM'!A37 -> V - 8.3
AC38: FORMULARIO
AC39: MAYUSCULAS | AD39: 0
AC40: DESCRIPCION | AD40: Numeros Romanos
AC41: ENUNCIADO | AD41: ="Escribe el Número Romano de "&Dato_01&"."
AC42: RESPUESTA 1 | AD42: =NUMERO.ROMANO(Dato_01)
AC43: PUNTOS 1 | AD43: 100
AC44: RETROALIM 1 | AD44: Muy bien.
...

Sheet Formulas PP
AD1: ad2
AD2: 10
AD3: 18
A4: =COUNTA(AC4:XFD4)-1 -> 1 | AC4: VARIABLES | AD4: NUM ROMANO (Palabra Perdida)
A5: PALABRA PERDIDA | AC5: DATO_01 | AD5: =ALEATORIO.ENTRE(1;10)
AC6: DATO_02 | AD6: =ALEATORIO.ENTRE(11;20)
AC7: DATO_03 | AD7: =ALEATORIO.ENTRE(21;30)
AC8: DATO_04 | AD8: =ALEATORIO.ENTRE(31;40)
AC9: DATO_05 | AD9: =NUMERO.ROMANO(Dato_01)
AC10: DATO_06 | AD10: =NUMERO.ROMANO(Dato_02)
AC11: DATO_07 | AD11: =NUMERO.ROMANO(Dato_03)
AC12: DATO_08 | AD12: =NUMERO.ROMANO(Dato_04)
AC13: DATO_09
AC14: DATO_10
AC15: DATO_11
AC16: DATO_12
AC17: DATO_13
AC18: DATO_14
AC19: DATO_15
AC20: DATO_16
A21: MISSING WORD | AC21: DATO_17 | AD21: =ALEATORIO.ENTRE(1;4)
AC22: DATO_18
AC23: DATO_19
AC24: DATO_20
AC25: DATO_21 | AD25: =ALEATORIO.ENTRE(5;8)
AC26: DATO_22
AC27: DATO_23
AC28: DATO_24
AC29: DATO_25
AC30: DATO_26
AC31: DATO_27
AC32: DATO_28
AC33: DATO_29
AC34: DATO_30
AC35: DATO_31
AC36: DATO_32
A37: ='Formulas OM'!A37 -> V - 8.3
AC38: FORMULARIO
AC39: DESCRIPCION | AD39: Numeros Romanos
AC40: ENUNCIADO | AD40: ="El Número Romano de "&INDIRECTO("Dato_0"&Dato_17)&" es [["&Dato_17+4&"]]. El Siguiente Número Romano "&INDIRECTO("Dato_0"&Dato_21)&" es [["&Dato_21-4&"]]."
...

Sheet Formulas EN
AD1: OK
AD2: 1
AD3: 9
A4: =COUNTA(AC4:XFD4)-1 -> 1 | AC4: VARIABLES | AD4: NUM ROMANOS (Siglo)
A5: ENSAYO | AC5: DATO_01 | AD5: =ALEATORIO.ENTRE(15;21)
AC6: DATO_02
AC7: DATO_03
AC8: DATO_04
AC9: DATO_05
AC10: DATO_06
AC11: DATO_07
AC12: DATO_08
AC13: DATO_09
AC14: DATO_10
AC15: DATO_11
AC16: DATO_12
AC17: DATO_13
... AC20: DATO_16
A21: ESSAY | AC21: DATO_17
AC22: DATO_18
AC23: DATO_19
AC24: DATO_19
AC25: DATO_19
AC26: DATO_22
AC27: DATO_23
AC28: DATO_24
AC29: DATO_25
AC30: DATO_26
AC31: DATO_27
AC32: DATO_28
AC33: DATO_29
... AC36: DATO_32
A37: ='Formulas OM'!A37 -> V - 8.3
AC38: FORMULARIO
AC39: DESCRIPCION | AD39: Numeros Romanos
AC40: ENUNCIADO | AD40: ="Escribe todo lo que sepas del Siglo "&NUMERO.ROMANO(Dato_01)&"."
AC41: Editor HTML | AD41: Editor HTML
AC42: TEXTO | AD42: Requerir al estudiante que introduzca texto
AC43: TAMAÑO CAJA | AD43: 10
AC44: ARCHIVOS | AD44: 2
...

Sheet Formulas CL
AD1: OK
AD2: 8
AD3: 3
A4: =COUNTA(AC4:XFD4)-1 -> 1 | AC4: VARIABLES | AD4: NUM ROMANOS (CL)
A5: ANIDADAS / CLOZE | AC5: DATO_01 | AD5: =ALEATORIO.ENTRE(1;10)
AC6: DATO_02 | AD6: =Dato_01+ALEATORIO.ENTRE(1;5)
AC7: DATO_03 | AD7: =Dato_01+ALEATORIO.ENTRE(6;10)
AC8: DATO_04 | AD8: =Dato_01+ALEATORIO.ENTRE(20;25)
AC9: DATO_05
AC10: DATO_06
AC11: DATO_07
AC12: DATO_08
AC13: DATO_09
AC14: DATO_10
AC15: DATO_11
AC16: DATO_12
AC17: DATO_13
AC18: DATO_14
AC19: DATO_15
AC20: DATO_16
A21: CLOZE | AC21: DATO_17 | AD21: =NUMERO.ROMANO(AB21)
AC22: DATO_18 | AD22: =NUMERO.ROMANO(AB22)
AC23: DATO_19 | AD23: =NUMERO.ROMANO(AB23)
AC24: DATO_20 | AD24: =NUMERO.ROMANO(AB24)
AC25: DATO_21
AC26: DATO_22
AC27: DATO_23
AC28: DATO_24
AC29: DATO_25
AC30: DATO_26
AC31: DATO_27
AC32: DATO_28
AC33: DATO_29
AC34: DATO_30
AC35: DATO_31
AC36: DATO_32
A37: ='Formulas OM'!A37 -> V - 8.3
AC38: FORMULARIO
AC39: DESCRIPCION | AD39: Numeros Romanos
AC40: ENUNCIADO | AD40: ="Trabajando con Números Romanos:<br><br> 1. Selecciona el Número Romano de "&Dato_01&" {1:MC:%100%"&Dato_17&"#Muy Bien~%-50%"&Dato_18&"#Debes estudiar más~%-50%"&Dato_19&"#Debes estudiar más~%-50%"&Dato_20&"#Debes estudiar más}<br><br> 2. Escribe el Número Romano de "&Dato_04&" {1:SA:%100%"&Dato_20&"#Muy bien~%50%"&MINUSC(Dato_20)&"#Ten cuidado y escribe en Mayúsculas}<br><br> 3. Escribe el número de "&Dato_19&"{1:NUMERICAL:%100%"&Dato_03&":0#Muy bien~%-50%"&Dato_02&":0#Debes estudiar mas}"
...
